# 错误处理

本章包含了 Rust 中错误处理的一些背景知识，以及 PyO3 如何将其与 Python 异常集成。

这部分内容提供了足够的细节，以创建一个 `#[pyfunction]`，该函数可以从 Rust 中产生的错误中引发 Python 异常。

指南后面有一节关于 [Python 异常](../exception.md)，更详细地介绍了异常类型。

## 表示 Python 异常

Rust 代码使用通用的 [`Result<T, E>`] 枚举来传播错误。错误类型 `E` 由代码作者选择，以描述可能发生的错误。

PyO3 有 [`PyErr`] 类型，用于表示 Python 异常。如果 PyO3 API 可能导致引发 Python 异常，则该 `API` 的返回类型将是 [`PyResult<T>`]，这是 `Result<T, PyErr>` 类型的别名。

总结如下：
- 当 Python 异常被引发并被 PyO3 捕获时，异常将存储在 `PyResult` 的 `Err` 变体中。
- 在 Rust 代码中传递 Python 异常时，使用所有“正常”的技术，例如 `?` 操作符，错误类型为 `PyErr`。
- 最后，当 `PyResult` 从 Rust 通过 PyO3 返回到 Python 时，如果结果是 `Err` 变体，则会引发包含的异常。

（关于 Rust 错误处理和 `?` 操作符有很多优秀的教程，因此本指南不会详细讨论 Rust 特定的主题。）

## 从函数中引发异常

如前一节所示，当包含 `Err` 的 `PyResult` 从 Rust 传递到 Python 时，PyO3 将引发其中包含的异常。

因此，要从 `#[pyfunction]` 中引发异常，请将返回类型 `T` 更改为 `PyResult<T>`。当函数返回 `Err` 时，它将引发 Python 异常。（只要错误 `E` 对 `PyErr` 有 `From` 转换，其他 `Result<T, E>` 类型也可以使用，见下文的 [自定义 Rust 错误类型](#custom-rust-error-types)。）

这同样适用于 `#[pymethods]` 中的函数。

例如，以下 `check_positive` 函数在输入为负数时引发 `ValueError`：

```rust
use pyo3::exceptions::PyValueError;
use pyo3::prelude::*;

#[pyfunction]
fn check_positive(x: i32) -> PyResult<()> {
    if x < 0 {
        Err(PyValueError::new_err("x is negative"))
    } else {
        Ok(())
    }
}
#
# fn main(){
# 	Python::with_gil(|py|{
# 		let fun = pyo3::wrap_pyfunction!(check_positive, py).unwrap();
# 		fun.call1((-1,)).unwrap_err();
# 		fun.call1((1,)).unwrap();
# 	});
# }
```

所有内置的 Python 异常类型都在 [`pyo3::exceptions`] 模块中定义。它们有一个 `new_err` 构造函数，可以直接构建 `PyErr`，如上例所示。

## 自定义 Rust 错误类型

只要为 `#[pyfunction]` 返回的 `Result<T, E>` 实现了 `std::from::From<E> for PyErr`，PyO3 将自动将其转换为 `PyResult<T>`。许多 Rust 标准库中的错误类型都以这种方式定义了 [`From`] 转换。

如果您处理的类型 `E` 是在第三方 crate 中定义的，请参见下文关于 [外部 Rust 错误类型](#foreign-rust-error-types) 的部分，以了解如何处理此错误。

以下示例利用了 `From<ParseIntError> for PyErr` 的实现，以引发在将字符串解析为整数时遇到的异常：

```rust
# use pyo3::prelude::*;
use std::num::ParseIntError;

#[pyfunction]
fn parse_int(x: &str) -> Result<usize, ParseIntError> {
    x.parse()
}

# fn main() {
#     Python::with_gil(|py| {
#         let fun = pyo3::wrap_pyfunction!(parse_int, py).unwrap();
#         let value: usize = fun.call1(("5",)).unwrap().extract().unwrap();
#         assert_eq!(value, 5);
#     });
# }
```

当传入一个不包含浮点数的字符串时，引发的异常将如下所示：

```python
>>> parse_int("bar")
Traceback (most recent call last):
  File "<stdin>", line 1, in <module>
ValueError: invalid digit found in string
```

作为一个更完整的示例，以下代码片段定义了一个名为 `CustomIOError` 的 Rust 错误。然后定义了 `From<CustomIOError> for PyErr`，返回一个表示 Python 的 `OSError` 的 `PyErr`。
因此，它可以直接在 `#[pyfunction]` 的结果中使用此错误，依赖于转换，如果需要传播到 Python 异常中。

```rust
use pyo3::exceptions::PyOSError;
use pyo3::prelude::*;
use std::fmt;

#[derive(Debug)]
struct CustomIOError;

impl std::error::Error for CustomIOError {}

impl fmt::Display for CustomIOError {
    fn fmt(&self, f: &mut fmt::Formatter<'_>) -> fmt::Result {
        write!(f, "Oh no!")
    }
}

impl std::convert::From<CustomIOError> for PyErr {
    fn from(err: CustomIOError) -> PyErr {
        PyOSError::new_err(err.to_string())
    }
}

pub struct Connection {/* ... */}

fn bind(addr: String) -> Result<Connection, CustomIOError> {
    if &addr == "0.0.0.0" {
        Err(CustomIOError)
    } else {
        Ok(Connection{ /* ... */})
    }
}

#[pyfunction]
fn connect(s: String) -> Result<(), CustomIOError> {
    bind(s)?;
    // 等等。
    Ok(())
}

fn main() {
    Python::with_gil(|py| {
        let fun = pyo3::wrap_pyfunction!(connect, py).unwrap();
        let err = fun.call1(("0.0.0.0",)).unwrap_err();
        assert!(err.is_instance_of::<PyOSError>(py));
    });
}
```

如果希望延迟构造 Python 异常实例，可以实现 [`PyErrArguments`]({{#PYO3_DOCS_URL}}/pyo3/trait.PyErrArguments.html) 特性，而不是 `From`。在这种情况下，实际的异常参数创建将延迟到需要 `PyErr` 时。

最后需要注意的是，任何具有 `From` 转换的错误 `E` 都可以与 `?`（“尝试”）操作符一起使用。以下是返回 `PyResult` 的 `parse_int` 的替代实现：

```rust
use pyo3::prelude::*;

fn parse_int(s: String) -> PyResult<usize> {
    let x = s.parse()?;
    Ok(x)
}
#
# use pyo3::exceptions::PyValueError;
#
# fn main() {
#     Python::with_gil(|py| {
#         assert_eq!(parse_int(String::from("1")).unwrap(), 1);
#         assert_eq!(parse_int(String::from("1337")).unwrap(), 1337);
#
#         assert!(parse_int(String::from("-1"))
#             .unwrap_err()
#             .is_instance_of::<PyValueError>(py));
#         assert!(parse_int(String::from("foo"))
#             .unwrap_err()
#             .is_instance_of::<PyValueError>(py));
#         assert!(parse_int(String::from("13.37"))
#             .unwrap_err()
#             .is_instance_of::<PyValueError>(py));
#     })
# }
```

## 外部 Rust 错误类型

Rust 编译器不允许为在定义该类型的 crate 之外的类型实现特性。（这被称为“孤儿规则”。）

对于在第三方代码中定义的类型 `OtherError`，有两种主要策略可以将其与 PyO3 集成：

- 创建一个新类型包装，例如 `MyOtherError`。然后实现 `From<MyOtherError> for PyErr`（或 `PyErrArguments`），以及 `From<OtherError>` 对 `MyOtherError`。
- 使用 Rust 的 Result 组合器，例如 `map_err`，自由编写代码将 `OtherError` 转换为所需的任何内容。这在每次使用时需要样板代码，但提供了无限的灵活性。

为了进一步详细说明新类型策略，关键技巧是从 `#[pyfunction]` 返回 `Result<T, MyOtherError>`。这意味着 PyO3 将利用 `From<MyOtherError> for PyErr` 来创建 Python 异常，而 `#[pyfunction]` 实现可以使用 `?` 自动将 `OtherError` 转换为 `MyOtherError`。

以下示例演示了这一点，假设有一个虚构的第三方 crate `some_crate`，其中的函数 `get_x` 返回 `Result<i32, OtherError>`：

```rust
# mod some_crate {
#   pub struct OtherError(());
#   impl OtherError {
#       pub fn message(&self) -> &'static str { "some error occurred" }
#   }
#   pub fn get_x() -> Result<i32, OtherError> { Ok(5) }
# }

use pyo3::prelude::*;
use pyo3::exceptions::PyValueError;
use some_crate::{OtherError, get_x};

struct MyOtherError(OtherError);

impl From<MyOtherError> for PyErr {
    fn from(error: MyOtherError) -> Self {
        PyValueError::new_err(error.0.message())
    }
}

impl From<OtherError> for MyOtherError {
    fn from(other: OtherError) -> Self {
        Self(other)
    }
}

#[pyfunction]
fn wrapped_get_x() -> Result<i32, MyOtherError> {
    // get_x 是一个返回 Result<i32, OtherError> 的函数
    let x: i32 = get_x()?;
    Ok(x)
}

# fn main() {
#     Python::with_gil(|py| {
#         let fun = pyo3::wrap_pyfunction!(wrapped_get_x, py).unwrap();
#         let value: usize = fun.call0().unwrap().extract().unwrap();
#         assert_eq!(value, 5);
#     });
# }
```

[`From`]: https://doc.rust-lang.org/stable/std/convert/trait.From.html
[`Result<T, E>`]: https://doc.rust-lang.org/stable/std/result/enum.Result.html
[`PyResult<T>`]: {{#PYO3_DOCS_URL}}/pyo3/prelude/type.PyResult.html
[`PyErr`]: {{#PYO3_DOCS_URL}}/pyo3/struct.PyErr.html
[`pyo3::exceptions`]: {{#PYO3_DOCS_URL}}/pyo3/exceptions/index.html