# Python 异常

## 定义一个新的异常

使用 [`create_exception!`] 宏：

```rust
use pyo3::create_exception;

create_exception!(module, MyError, pyo3::exceptions::PyException);
```

* `module` 是包含模块的名称。
* `MyError` 是新异常类型的名称。

例如：

```rust
use pyo3::prelude::*;
use pyo3::create_exception;
use pyo3::types::IntoPyDict;
use pyo3::exceptions::PyException;

create_exception!(mymodule, CustomError, PyException);

Python::with_gil(|py| {
    let ctx = [("CustomError", py.get_type_bound::<CustomError>())].into_py_dict_bound(py);
    pyo3::py_run!(
        py,
        *ctx,
        "assert str(CustomError) == \"<class 'mymodule.CustomError'>\""
    );
    pyo3::py_run!(py, *ctx, "assert CustomError('oops').args == ('oops',)");
});
```

在使用 PyO3 创建扩展模块时，可以像这样将新异常添加到模块中，以便可以从 Python 导入：

```rust
use pyo3::prelude::*;
use pyo3::exceptions::PyException;

pyo3::create_exception!(mymodule, CustomError, PyException);

#[pymodule]
fn mymodule(py: Python<'_>, m: &Bound<'_, PyModule>) -> PyResult<()> {
    // ... 添加到模块的其他元素 ...
    m.add("CustomError", py.get_type_bound::<CustomError>())?;

    Ok(())
}
```

## 引发异常

如 [函数错误处理](./function/error-handling.md) 章节所述，要从 `#[pyfunction]` 或 `#[pymethods]` 引发异常，返回 `Err(PyErr)`。PyO3 会在将结果返回给 Python 时自动引发此异常。

您还可以手动在 Python 解释器的全局状态中写入和获取错误：

```rust
use pyo3::{Python, PyErr};
use pyo3::exceptions::PyTypeError;

Python::with_gil(|py| {
    PyTypeError::new_err("Error").restore(py);
    assert!(PyErr::occurred(py));
    drop(PyErr::fetch(py));
});
```

## 检查异常类型

Python 有一个 [`isinstance`](https://docs.python.org/3/library/functions.html#isinstance) 方法来检查对象的类型。在 PyO3 中，每个对象都有 [`PyAny::is_instance`] 和 [`PyAny::is_instance_of`] 方法，功能相同。

```rust
use pyo3::prelude::*;
use pyo3::types::{PyBool, PyList};

Python::with_gil(|py| {
    assert!(PyBool::new_bound(py, true).is_instance_of::<PyBool>());
    let list = PyList::new(py, &[1, 2, 3, 4]);
    assert!(!list.is_instance_of::<PyBool>());
    assert!(list.is_instance_of::<PyList>());
});
```

要检查异常的类型，您可以类似地执行：

```rust
# use pyo3::exceptions::PyTypeError;
# use pyo3::prelude::*;
# Python::with_gil(|py| {
# let err = PyTypeError::new_err(());
err.is_instance_of::<PyTypeError>(py);
# });
```

## 使用在 Python 代码中定义的异常

可以将 Python 代码中定义的异常作为原生 Rust 类型使用。`import_exception!` 宏允许导入特定的异常类，并为该异常定义一个 Rust 类型。

```rust
#![allow(dead_code)]
use pyo3::prelude::*;

mod io {
    pyo3::import_exception!(io, UnsupportedOperation);
}

fn tell(file: &Bound<'_, PyAny>) -> PyResult<u64> {
    match file.call_method0("tell") {
        Err(_) => Err(io::UnsupportedOperation::new_err("not supported: tell")),
        Ok(x) => x.extract::<u64>(),
    }
}
```

[`pyo3::exceptions`]({{#PYO3_DOCS_URL}}/pyo3/exceptions/index.html) 定义了多个标准库模块的异常。

[`create_exception!`]: {{#PYO3_DOCS_URL}}/pyo3/macro.create_exception.html
[`import_exception!`]: {{#PYO3_DOCS_URL}}/pyo3/macro.import_exception.html

[`PyErr`]: {{#PYO3_DOCS_URL}}/pyo3/struct.PyErr.html
[`PyResult`]: {{#PYO3_DOCS_URL}}/pyo3/type.PyResult.html
[`PyErr::from_value`]: {{#PYO3_DOCS_URL}}/pyo3/struct.PyErr.html#method.from_value
[`PyAny::is_instance`]: {{#PYO3_DOCS_URL}}/pyo3/types/trait.PyAnyMethods.html#tymethod.is_instance
[`PyAny::is_instance_of`]: {{#PYO3_DOCS_URL}}/pyo3/types/trait.PyAnyMethods.html#tymethod.is_instance_of